# Exceções encadeadas

* Muitas vezes a captura e tratamento de uma exceção vai acabar lançando uma nova exceção
* Por exemplo: ao tentar acessar um objeto inexistente na memória, o sistema pode capturar a exceção do tipo ArrayOutOfBounds e lançar outra
* Um método que faz uso do primeiro e está mais acima na pilha de chamadas poderá fazer o mesmo e assim sucessivbamente
* Para manter o registro das exceções encadeadas, sugere-se criar a nova exceção usando o construtor **Throwable(String, Throable)**, cujos parâmetros são a mensagem da exceção atual e a exceção causa.
* Também é possível usar o construtro **Throable(Thworalbe)**, ou o método **initCause(Throwable): Throwable**

```java
  try {

  } catch (IOException e) {
      throw new SampleException("Other IOException", e);
  }
```

* O método de instância **getStackStrace()** da classe **Throwable** permite obter a pilha de exceções encadeadas que foram lançadas

Logging API
The next code snippet logs where an exception occurred from within the catch block. However, rather than manually parsing the stack trace and sending the output to System.err(), it sends the output to a file using the logging facility in the java.util.logging package.

try {
    Handler handler = new FileHandler("OutFile.log");
    Logger.getLogger("").addHandler(handler);
    
} catch (IOException e) {
    Logger logger = Logger.getLogger("package.name"); 
    StackTraceElement elements[] = e.getStackTrace();
    for (int i = 0, n = elements.length; i < n; i++) {
        logger.log(Level.WARNING, elements[i].getMethodName());
    }
}
